Workbook
Name ERP: [1]FCFF!$F$21
Name ERP: #REF!
Name ERP: FCFF!$F$22
Name RF: [1]FCFF!$F$20
Name RF: #REF!
Name RF: FCFF!$F$21
Name rf_rate: #REF!
Name rf_rate: FCFF!$F$21
Name tap_rate: [1]FCFF!$F$18
Name tap_rate: #REF!
Name tap_rate: FCFF!$F$19
Name Taper_rate: #REF!
Name Taper_rate: FCFF!$C$21
Name tax_rate: [1]FCFF!$F$22
Name tax_rate: #REF!
Name tax_rate: FCFF!$F$23
Name UPDATE: '[1]Data sheet'!$E$1
Name UPDATE: '[2]Data Sheet'!$E$1
Name UPDATE: 'Data Sheet'!$E$1

Sheet Profit & Loss
A1: ='Data Sheet'!B1 -> JSW STEEL LTD | H1: =UPDATE -> JSW STEEL LTD | M1: SCREENER.IN
A3: Narration | B3: ='Data Sheet'!B16 -> 42825 | C3: ='Data Sheet'!C16 -> 43190 | D3: ='Data Sheet'!D16 -> 43555 | E3: ='Data Sheet'!E16 -> 43921 | F3: ='Data Sheet'!F16 -> 44286 | G3: ='Data Sheet'!G16 -> 44651 | H3: ='Data Sheet'!H16 -> 45016 | I3: ='Data Sheet'!I16 -> 45382 | ... K3: ='Data Sheet'!K16 -> 46112 | L3: Trailing | M3: Best Case | N3: Worst Case
A4: Sales | B4: ='Data Sheet'!B17 -> 55604 | C4: ='Data Sheet'!C17 -> 71933 | D4: ='Data Sheet'!D17 -> 84757 | E4: ='Data Sheet'!E17 -> 73326 | F4: ='Data Sheet'!F17 -> 79839 | G4: ='Data Sheet'!G17 -> 146371 | H4: ='Data Sheet'!H17 -> 165960 | I4: ='Data Sheet'!I17 -> 175006 | ... K4: ='Data Sheet'!K17 -> 185470 | L4: =SUM(Quarters!H4:K4) -> 185470 | M4: =$K4+M23*K4 -> 203757.29 | N4: =$K4+N23*L4 -> 192470.31
A5: Expenses | B5: =SUM('Data Sheet'!B18,'Data Sheet'!B20:B24, -1*'Data Sheet'!B19) -> 43296 | C5: =SUM('Data Sheet'!C18,'Data Sheet'!C20:C24, -1*'Data Sheet'!C19) -> 57017 | D5: =SUM('Data Sheet'!D18,'Data Sheet'!D20:D24, -1*'Data Sheet'!D19) -> 65827 | E5: =SUM('Data Sheet'!E18,'Data Sheet'!E20:E24, -1*'Data Sheet'!E19) -> 61513 | F5: =SUM('Data Sheet'!F18,'Data Sheet'!F20:F24, -1*'Data Sheet'!F19) -> 59661 | G5: =SUM('Data Sheet'!G18,'Data Sheet'!G20:G24, -1*'Data Sheet'!G19) -> 107257 | H5: =SUM('Data Sheet'!H18,'Data Sheet'!H20:H24, -1*'Data Sheet'!H19) -> 147490 | I5: =SUM('Data Sheet'!I18,'Data Sheet'!I20:I24, -1*'Data Sheet'!I19) -> 146849 | ... K5: =SUM('Data Sheet'!K18,'Data Sheet'!K20:K24, -1*'Data Sheet'!K19) -> 156124 | L5: =SUM(Quarters!H5:K5) -> 156124 | M5: =M4-M6 -> 171517.78 | N5: =N4-N6 -> 163296.86
A6: Operating Profit | B6: =B4-B5 -> 12308 | C6: =C4-C5 -> 14916 | D6: =D4-D5 -> 18930 | E6: =E4-E5 -> 11813 | F6: =F4-F5 -> 20178 | G6: =G4-G5 -> 39114 | H6: =H4-H5 -> 18470 | I6: =I4-I5 -> 28157 | ... K6: =K4-K5 -> 29346 | L6: =SUM(Quarters!H6:K6) -> 29346 | M6: =M4*M24 -> 32239.508 | N6: =N4*N24 -> 29173.452
A7: Other Income | B7: ='Data Sheet'!B25 -> 18 | C7: ='Data Sheet'!C25 -> -177 | D7: ='Data Sheet'!D25 -> 196 | E7: ='Data Sheet'!E25 -> -289 | F7: ='Data Sheet'!F25 -> 473 | G7: ='Data Sheet'!G25 -> 1600 | H7: ='Data Sheet'!H25 -> 1561 | I7: ='Data Sheet'!I25 -> 1500 | ... K7: ='Data Sheet'!K25 -> 18607 | L7: =SUM(Quarters!H7:K7) -> 18607 | M7: 0 | N7: 0
A8: Depreciation | B8: ='Data Sheet'!B26 -> 3430 | C8: ='Data Sheet'!C26 -> 3387 | D8: ='Data Sheet'!D26 -> 4041 | E8: ='Data Sheet'!E26 -> 4246 | F8: ='Data Sheet'!F26 -> 4679 | G8: ='Data Sheet'!G26 -> 6001 | H8: ='Data Sheet'!H26 -> 7474 | I8: ='Data Sheet'!I26 -> 8172 | ... K8: ='Data Sheet'!K26 -> 9601 | L8: =SUM(Quarters!H8:K8) -> 9601 | M8: =+$L8 -> 9601 | N8: =+$L8 -> 9601
A9: Interest | B9: ='Data Sheet'!B27 -> 3768 | C9: ='Data Sheet'!C27 -> 3701 | D9: ='Data Sheet'!D27 -> 3917 | E9: ='Data Sheet'!E27 -> 4265 | F9: ='Data Sheet'!F27 -> 3957 | G9: ='Data Sheet'!G27 -> 4968 | H9: ='Data Sheet'!H27 -> 6902 | I9: ='Data Sheet'!I27 -> 8105 | ... K9: ='Data Sheet'!K27 -> 9102 | L9: =SUM(Quarters!H9:K9) -> 9102 | M9: =+$L9 -> 9102 | N9: =+$L9 -> 9102
A10: Profit before tax | B10: ='Data Sheet'!B28 -> 5128 | C10: ='Data Sheet'!C28 -> 7651 | D10: ='Data Sheet'!D28 -> 11168 | E10: ='Data Sheet'!E28 -> 3013 | F10: ='Data Sheet'!F28 -> 12015 | G10: ='Data Sheet'!G28 -> 29745 | H10: ='Data Sheet'!H28 -> 5655 | I10: ='Data Sheet'!I28 -> 13380 | ... K10: ='Data Sheet'!K28 -> 29250 | L10: =SUM(Quarters!H10:K10) -> 29250 | M10: =M6+M7-SUM(M8:M9) -> 13536.508 | N10: =N6+N7-SUM(N8:N9) -> 10470.452
A11: Tax | B11: ='Data Sheet'!B29 -> 1674 | C11: ='Data Sheet'!C29 -> 1538 | D11: ='Data Sheet'!D29 -> 3644 | E11: ='Data Sheet'!E29 -> -906 | F11: ='Data Sheet'!F29 -> 4142 | G11: ='Data Sheet'!G29 -> 8807 | H11: ='Data Sheet'!H29 -> 1516 | I11: ='Data Sheet'!I29 -> 4407 | ... K11: ='Data Sheet'!K29 -> 3742 | L11: =SUM(Quarters!H11:K11) -> 3742 | M11: =IF($L10>0,$L11/$L10,0) -> 0.12793162 | N11: =IF($L10>0,$L11/$L10,0) -> 0.12793162
A12: Net profit | B12: ='Data Sheet'!B30 -> 3523 | C12: ='Data Sheet'!C30 -> 6214 | D12: ='Data Sheet'!D30 -> 7639 | E12: ='Data Sheet'!E30 -> 4030 | F12: ='Data Sheet'!F30 -> 7911 | G12: ='Data Sheet'!G30 -> 20665 | H12: ='Data Sheet'!H30 -> 4144 | I12: ='Data Sheet'!I30 -> 8812 | ... K12: ='Data Sheet'!K30 -> 22316 | L12: =SUM(Quarters!H12:K12) -> 22316 | M12: =M10-M11*M10 -> 11804.76 | N12: =N10-N11*N10 -> 9130.9504
A13: EPS | B13: =IF('Data Sheet'!B93>0,B12/'Data Sheet'!B93,0) -> 14.574715 | C13: =IF('Data Sheet'!C93>0,C12/'Data Sheet'!C93,0) -> 25.70743 | D13: =IF('Data Sheet'!D93>0,D12/'Data Sheet'!D93,0) -> 31.602681 | E13: =IF('Data Sheet'!E93>0,E12/'Data Sheet'!E93,0) -> 16.672183 | F13: =IF('Data Sheet'!F93>0,F12/'Data Sheet'!F93,0) -> 32.72795 | G13: =IF('Data Sheet'!G93>0,G12/'Data Sheet'!G93,0) -> 85.491478 | H13: =IF('Data Sheet'!H93>0,H12/'Data Sheet'!H93,0) -> 17.143803 | I13: =IF('Data Sheet'!I93>0,I12/'Data Sheet'!I93,0) -> 36.033531 | ... K13: =IF('Data Sheet'!K93>0,K12/'Data Sheet'!K93,0) -> 91.253322 | L13: =IF('Data Sheet'!$B6>0,'Profit & Loss'!L12/'Data Sheet'!$B6,0) -> 91.255039 | M13: =IF('Data Sheet'!$B6>0,'Profit & Loss'!M12/'Data Sheet'!$B6,0) -> 48.272264 | N13: =IF('Data Sheet'!$B6>0,'Profit & Loss'!N12/'Data Sheet'!$B6,0) -> 37.338467
A14: Price to earning | B14: =IF(B15>0,B15/B13,"") -> 12.912774 | C14: =IF(C15>0,C15/C13,"") -> 11.208822 | D14: =IF(D15>0,D15/D13,"") -> 9.2729475 | E14: =IF(E15>0,E15/E13,"") -> 8.7720968 | F14: =IF(F15>0,F15/F13,"") -> 14.313454 | G14: =IF(G15>0,G15/G13,"") -> 8.5698601 | H14: =IF(H15>0,H15/H13,"") -> 40.136953 | I14: =IF(I15>0,I15/I13,"") -> 23.039652 | ... K14: =IF(K15>0,K15/K13,"") -> 12.300922 | L14: =IF(L13>0,L15/L13,0) -> 14.004706 | M14: =M25 -> 30.886945 | N14: =N25 -> 14.004706
A15: Price | B15: ='Data Sheet'!B90 -> 188.2 | C15: ='Data Sheet'!C90 -> 288.15 | D15: ='Data Sheet'!D90 -> 293.05 | E15: ='Data Sheet'!E90 -> 146.25 | F15: ='Data Sheet'!F90 -> 468.45 | G15: ='Data Sheet'!G90 -> 732.65 | H15: ='Data Sheet'!H90 -> 688.1 | I15: ='Data Sheet'!I90 -> 830.2 | ... K15: ='Data Sheet'!K90 -> 1122.5 | L15: ='Data Sheet'!B8 -> 1278 | M15: =M13*M14 -> 1490.9828 | N15: =N13*N14 -> 522.91426
A17: RATIOS:
A18: Dividend Payout | B18: =IF('Data Sheet'!B30>0, 'Data Sheet'!B31/'Data Sheet'!B30, 0) -> 0.19223673 | C18: =IF('Data Sheet'!C30>0, 'Data Sheet'!C31/'Data Sheet'!C30, 0) -> 0.15551979 | D18: =IF('Data Sheet'!D30>0, 'Data Sheet'!D31/'Data Sheet'!D30, 0) -> 0.16155256 | E18: =IF('Data Sheet'!E30>0, 'Data Sheet'!E31/'Data Sheet'!E30, 0) -> 0.14937965 | F18: =IF('Data Sheet'!F30>0, 'Data Sheet'!F31/'Data Sheet'!F30, 0) -> 0.24813551 | G18: =IF('Data Sheet'!G30>0, 'Data Sheet'!G31/'Data Sheet'!G30, 0) -> 0.25271474 | H18: =IF('Data Sheet'!H30>0, 'Data Sheet'!H31/'Data Sheet'!H30, 0) -> 0.24695946 | I18: =IF('Data Sheet'!I30>0, 'Data Sheet'!I31/'Data Sheet'!I30, 0) -> 0.25266682 | ... K18: =IF('Data Sheet'!K30>0, 'Data Sheet'!K31/'Data Sheet'!K30, 0) -> 0.097038
A19: OPM | B19: =IF(B6>0,B6/B4,0) -> 0.22135098 | C19: =IF(C6>0,C6/C4,0) -> 0.20735963 | D19: =IF(D6>0,D6/D4,0) -> 0.22334438 | E19: =IF(E6>0,E6/E4,0) -> 0.16110247 | F19: =IF(F6>0,F6/F4,0) -> 0.25273363 | G19: =IF(G6>0,G6/G4,0) -> 0.26722507 | H19: =IF(H6>0,H6/H4,0) -> 0.11129188 | I19: =IF(I6>0,I6/I4,0) -> 0.16089163 | ... L19: =IF(L6>0,L6/L4,0) -> 0.15822505
G22: TRENDS: | H22: 10 YEARS | I22: 7 YEARS | J22: 5 YEARS | K22: 3 YEARS | L22: RECENT | M22: BEST | N22: WORST
G23: Sales Growth | H23: =IF(B4=0,"",POWER($K4/B4,1/9)-1) -> 0.1432198 | I23: =IF(D4=0,"",POWER($K4/D4,1/7)-1) -> 0.11836983 | J23: =IF(F4=0,"",POWER($K4/F4,1/5)-1) -> 0.18361842 | K23: =IF(H4=0,"",POWER($K4/H4, 1/3)-1) -> 0.037743644 | L23: =IF(ISERROR(MAX(IF(J4=0,"",(K4-J4)/J4),IF(K4=0,"",(L4-K4)/K4))),"",MAX(IF(J4=0,"",(K4-J4)/J4),IF(K4=0,"",(L4-K4)/K4))) -> 0.098599725 | M23: =MAX(K23:L23) -> 0.098599725 | N23: =MIN(H23:L23) -> 0.037743644
G24: OPM | H24: =IF(SUM(B4:$K$4)=0,"",SUMPRODUCT(B19:$K$19,B4:$K$4)/SUM(B4:$K$4)) -> 0.17890712 | I24: =IF(SUM(E4:$K$4)=0,"",SUMPRODUCT(E19:$K$19,E4:$K$4)/SUM(E4:$K$4)) -> 0.17069128 | J24: =IF(SUM(G4:$K$4)=0,"",SUMPRODUCT(G19:$K$19,G4:$K$4)/SUM(G4:$K$4)) -> 0.16374397 | K24: =IF(SUM(I4:$K$4)=0, "", SUMPRODUCT(I19:$K$19,I4:$K$4)/SUM(I4:$K$4)) -> 0.15157378 | L24: =L19 -> 0.15822505 | M24: =MAX(K24:L24) -> 0.15822505 | N24: =MIN(H24:L24) -> 0.15157378
G25: Price to Earning | H25: =IF(ISERROR(AVERAGEIF(B14:$L14,">0")),"",AVERAGEIF(B14:$L14,">0")) -> 20.794062 | I25: =IF(ISERROR(AVERAGEIF(E14:$L14,">0")),"",AVERAGEIF(E14:$L14,">0")) -> 24.417518 | J25: =IF(ISERROR(AVERAGEIF(G14:$L14,">0")),"",AVERAGEIF(G14:$L14,">0")) -> 28.709099 | K25: =IF(ISERROR(AVERAGEIF(I14:$L14,">0")),"",AVERAGEIF(I14:$L14,">0")) -> 30.886945 | L25: =L14 -> 14.004706 | M25: =MAX(K25:L25) -> 30.886945 | N25: =MIN(H25:L25) -> 14.004706

Sheet Quarters
A1: ='Profit & Loss'!A1 -> JSW STEEL LTD | E1: =UPDATE -> JSW STEEL LTD | J1: SCREENER.IN
A3: Narration | B3: ='Data Sheet'!B41 -> 45291 | C3: ='Data Sheet'!C41 -> 45382 | D3: ='Data Sheet'!D41 -> 45473 | E3: ='Data Sheet'!E41 -> 45565 | F3: ='Data Sheet'!F41 -> 45657 | G3: ='Data Sheet'!G41 -> 45747 | H3: ='Data Sheet'!H41 -> 45838 | I3: ='Data Sheet'!I41 -> 45930 | ... K3: ='Data Sheet'!K41 -> 46112
A4: Sales | B4: ='Data Sheet'!B42 -> 41940 | C4: ='Data Sheet'!C42 -> 46269 | D4: ='Data Sheet'!D42 -> 42943 | E4: ='Data Sheet'!E42 -> 39684 | F4: ='Data Sheet'!F42 -> 41378 | G4: ='Data Sheet'!G42 -> 44819 | H4: ='Data Sheet'!H42 -> 43147 | I4: ='Data Sheet'!I42 -> 45152 | ... K4: ='Data Sheet'!K42 -> 51180
A5: Expenses | B5: ='Data Sheet'!B43 -> 34776 | C5: ='Data Sheet'!C43 -> 40243 | D5: ='Data Sheet'!D43 -> 37445 | E5: ='Data Sheet'!E43 -> 34309 | F5: ='Data Sheet'!F43 -> 35799 | G5: ='Data Sheet'!G43 -> 38684 | H5: ='Data Sheet'!H43 -> 35671 | I5: ='Data Sheet'!I43 -> 38125 | ... K5: ='Data Sheet'!K43 -> 42716
A6: Operating Profit | B6: ='Data Sheet'!B50 -> 7164 | C6: ='Data Sheet'!C50 -> 6026 | D6: ='Data Sheet'!D50 -> 5498 | E6: ='Data Sheet'!E50 -> 5375 | F6: ='Data Sheet'!F50 -> 5579 | G6: ='Data Sheet'!G50 -> 6135 | H6: ='Data Sheet'!H50 -> 7476 | I6: ='Data Sheet'!I50 -> 7027 | ... K6: ='Data Sheet'!K50 -> 8464
A7: Other Income | B7: ='Data Sheet'!B44 -> 194 | C7: ='Data Sheet'!C44 -> 242 | D7: ='Data Sheet'!D44 -> 164 | E7: ='Data Sheet'!E44 -> -189 | F7: ='Data Sheet'!F44 -> 50 | G7: ='Data Sheet'!G44 -> 186 | H7: ='Data Sheet'!H44 -> 350 | I7: ='Data Sheet'!I44 -> 284 | ... K7: ='Data Sheet'!K44 -> 18229
A8: Depreciation | B8: ='Data Sheet'!B45 -> 2059 | C8: ='Data Sheet'!C45 -> 2194 | D8: ='Data Sheet'!D45 -> 2209 | E8: ='Data Sheet'!E45 -> 2267 | F8: ='Data Sheet'!F45 -> 2336 | G8: ='Data Sheet'!G45 -> 2497 | H8: ='Data Sheet'!H45 -> 2537 | I8: ='Data Sheet'!I45 -> 2554 | ... K8: ='Data Sheet'!K45 -> 2148
A9: Interest | B9: ='Data Sheet'!B46 -> 1996 | C9: ='Data Sheet'!C46 -> 2062 | D9: ='Data Sheet'!D46 -> 2073 | E9: ='Data Sheet'!E46 -> 2130 | F9: ='Data Sheet'!F46 -> 2115 | G9: ='Data Sheet'!G46 -> 2094 | H9: ='Data Sheet'!H46 -> 2217 | I9: ='Data Sheet'!I46 -> 2413 | ... K9: ='Data Sheet'!K46 -> 2168
A10: Profit before tax | B10: ='Data Sheet'!B47 -> 3303 | C10: ='Data Sheet'!C47 -> 2012 | D10: ='Data Sheet'!D47 -> 1380 | E10: ='Data Sheet'!E47 -> 789 | F10: ='Data Sheet'!F47 -> 1178 | G10: ='Data Sheet'!G47 -> 1730 | H10: ='Data Sheet'!H47 -> 3072 | I10: ='Data Sheet'!I47 -> 2344 | ... K10: ='Data Sheet'!K47 -> 22377
A11: Tax | B11: ='Data Sheet'!B48 -> 853 | C11: ='Data Sheet'!C48 -> 690 | D11: ='Data Sheet'!D48 -> 513 | E11: ='Data Sheet'!E48 -> 385 | F11: ='Data Sheet'!F48 -> 459 | G11: ='Data Sheet'!G48 -> 229 | H11: ='Data Sheet'!H48 -> 863 | I11: ='Data Sheet'!I48 -> 698 | ... K11: ='Data Sheet'!K48 -> 3134
A12: Net profit | B12: ='Data Sheet'!B49 -> 2415 | C12: ='Data Sheet'!C49 -> 1299 | D12: ='Data Sheet'!D49 -> 845 | E12: ='Data Sheet'!E49 -> 439 | F12: ='Data Sheet'!F49 -> 717 | G12: ='Data Sheet'!G49 -> 1503 | H12: ='Data Sheet'!H49 -> 2184 | I12: ='Data Sheet'!I49 -> 1623 | ... K12: ='Data Sheet'!K49 -> 16370
A14: OPM | B14: =IF(B4>0,B6/B4,"") -> 0.17081545 | C14: =IF(C4>0,C6/C4,"") -> 0.13023839 | D14: =IF(D4>0,D6/D4,"") -> 0.12803018 | E14: =IF(E4>0,E6/E4,"") -> 0.13544502 | F14: =IF(F4>0,F6/F4,"") -> 0.1348301 | G14: =IF(G4>0,G6/G4,"") -> 0.13688391 | H14: =IF(H4>0,H6/H4,"") -> 0.17326813 | I14: =IF(I4>0,I6/I4,"") -> 0.15562987 | ... K14: =IF(K4>0,K6/K4,"") -> 0.1653771

Sheet Balance Sheet
A1: ='Profit & Loss'!A1 -> JSW STEEL LTD | E1: =UPDATE -> JSW STEEL LTD | J1: SCREENER.IN
A3: Narration | B3: ='Data Sheet'!B56 -> 42825 | C3: ='Data Sheet'!C56 -> 43190 | D3: ='Data Sheet'!D56 -> 43555 | E3: ='Data Sheet'!E56 -> 43921 | F3: ='Data Sheet'!F56 -> 44286 | G3: ='Data Sheet'!G56 -> 44651 | H3: ='Data Sheet'!H56 -> 45016 | I3: ='Data Sheet'!I56 -> 45382 | ... K3: ='Data Sheet'!K56 -> 46112
A4: Equity Share Capital | B4: ='Data Sheet'!B57 -> 301 | C4: ='Data Sheet'!C57 -> 302 | D4: ='Data Sheet'!D57 -> 301 | E4: ='Data Sheet'!E57 -> 301 | F4: ='Data Sheet'!F57 -> 302 | G4: ='Data Sheet'!G57 -> 301 | H4: ='Data Sheet'!H57 -> 301 | I4: ='Data Sheet'!I57 -> 305 | ... K4: ='Data Sheet'!K57 -> 305
A5: Reserves | B5: ='Data Sheet'!B58 -> 22346 | C5: ='Data Sheet'!C58 -> 27696 | D5: ='Data Sheet'!D58 -> 34494 | E5: ='Data Sheet'!E58 -> 36298 | F5: ='Data Sheet'!F58 -> 45308 | G5: ='Data Sheet'!G58 -> 66996 | H5: ='Data Sheet'!H58 -> 65394 | I5: ='Data Sheet'!I58 -> 77364 | ... K5: ='Data Sheet'!K58 -> 99748
A6: Borrowings | B6: ='Data Sheet'!B59 -> 43334 | C6: ='Data Sheet'!C59 -> 39393 | D6: ='Data Sheet'!D59 -> 47396 | E6: ='Data Sheet'!E59 -> 61423 | F6: ='Data Sheet'!F59 -> 66727 | G6: ='Data Sheet'!G59 -> 72237 | H6: ='Data Sheet'!H59 -> 80853 | I6: ='Data Sheet'!I59 -> 87984 | ... K6: ='Data Sheet'!K59 -> 99310
A7: Other Liabilities | B7: ='Data Sheet'!B60 -> 22024 | C7: ='Data Sheet'!C60 -> 24579 | D7: ='Data Sheet'!D60 -> 32606 | E7: ='Data Sheet'!E60 -> 33798 | F7: ='Data Sheet'!F60 -> 34826 | G7: ='Data Sheet'!G60 -> 56951 | H7: ='Data Sheet'!H60 -> 63991 | I7: ='Data Sheet'!I60 -> 62245 | ... K7: ='Data Sheet'!K60 -> 70313
A8: Total | B8: ='Data Sheet'!B61 -> 88005 | C8: ='Data Sheet'!C61 -> 91970 | D8: ='Data Sheet'!D61 -> 114797 | E8: ='Data Sheet'!E61 -> 131820 | F8: ='Data Sheet'!F61 -> 147163 | G8: ='Data Sheet'!G61 -> 196485 | H8: ='Data Sheet'!H61 -> 210539 | I8: ='Data Sheet'!I61 -> 227898 | ... K8: ='Data Sheet'!K61 -> 269676
A10: Net Block | B10: ='Data Sheet'!B62 -> 58730 | C10: ='Data Sheet'!C62 -> 57848 | D10: ='Data Sheet'!D62 -> 62644 | E10: ='Data Sheet'!E62 -> 62085 | F10: ='Data Sheet'!F62 -> 64917 | G10: ='Data Sheet'!G62 -> 99880 | H10: ='Data Sheet'!H62 -> 104452 | I10: ='Data Sheet'!I62 -> 112461 | ... K10: ='Data Sheet'!K62 -> 117552
A11: Capital Work in Progress | B11: ='Data Sheet'!B63 -> 4363 | C11: ='Data Sheet'!C63 -> 5950 | D11: ='Data Sheet'!D63 -> 11889 | E11: ='Data Sheet'!E63 -> 27191 | F11: ='Data Sheet'!F63 -> 32566 | G11: ='Data Sheet'!G63 -> 16905 | H11: ='Data Sheet'!H63 -> 22166 | I11: ='Data Sheet'!I63 -> 29676 | ... K11: ='Data Sheet'!K63 -> 21892
A12: Investments | B12: ='Data Sheet'!B64 -> 1366 | C12: ='Data Sheet'!C64 -> 1469 | D12: ='Data Sheet'!D64 -> 1894 | E12: ='Data Sheet'!E64 -> 1259 | F12: ='Data Sheet'!F64 -> 7427 | G12: ='Data Sheet'!G64 -> 4940 | H12: ='Data Sheet'!H64 -> 4806 | I12: ='Data Sheet'!I64 -> 7246 | ... K12: ='Data Sheet'!K64 -> 10218
A13: Other Assets | B13: ='Data Sheet'!B65 -> 23546 | C13: ='Data Sheet'!C65 -> 26703 | D13: ='Data Sheet'!D65 -> 38370 | E13: ='Data Sheet'!E65 -> 41285 | F13: ='Data Sheet'!F65 -> 42253 | G13: ='Data Sheet'!G65 -> 74760 | H13: ='Data Sheet'!H65 -> 79115 | I13: ='Data Sheet'!I65 -> 78515 | ... K13: ='Data Sheet'!K65 -> 120014
A14: Total | B14: ='Data Sheet'!B66 -> 88005 | C14: ='Data Sheet'!C66 -> 91970 | D14: ='Data Sheet'!D66 -> 114797 | E14: ='Data Sheet'!E66 -> 131820 | F14: ='Data Sheet'!F66 -> 147163 | G14: ='Data Sheet'!G66 -> 196485 | H14: ='Data Sheet'!H66 -> 210539 | I14: ='Data Sheet'!I66 -> 227898 | ... K14: ='Data Sheet'!K66 -> 269676
A16: Working Capital | B16: =B13-B7 -> 1522 | C16: =C13-C7 -> 2124 | D16: =D13-D7 -> 5764 | E16: =E13-E7 -> 7487 | F16: =F13-F7 -> 7427 | G16: =G13-G7 -> 17809 | H16: =H13-H7 -> 15124 | I16: =I13-I7 -> 16270 | ... K16: =K13-K7 -> 49701
A17: Debtors | B17: ='Data Sheet'!B67 -> 4149 | C17: ='Data Sheet'!C67 -> 4704 | D17: ='Data Sheet'!D67 -> 7160 | E17: ='Data Sheet'!E67 -> 4505 | F17: ='Data Sheet'!F67 -> 4486 | G17: ='Data Sheet'!G67 -> 7457 | H17: ='Data Sheet'!H67 -> 7134 | I17: ='Data Sheet'!I67 -> 7548 | ... K17: ='Data Sheet'!K67 -> 11260
A18: Inventory | B18: ='Data Sheet'!B68 -> 11395 | C18: ='Data Sheet'!C68 -> 12594 | D18: ='Data Sheet'!D68 -> 14548 | E18: ='Data Sheet'!E68 -> 13773 | F18: ='Data Sheet'!F68 -> 14249 | G18: ='Data Sheet'!G68 -> 33787 | H18: ='Data Sheet'!H68 -> 33135 | I18: ='Data Sheet'!I68 -> 37815 | ... K18: ='Data Sheet'!K68 -> 32765
A20: Debtor Days | B20: =IF('Profit & Loss'!B4>0,'Balance Sheet'!B17/('Profit & Loss'!B4/365),0) -> 27.235181 | C20: =IF('Profit & Loss'!C4>0,'Balance Sheet'!C17/('Profit & Loss'!C4/365),0) -> 23.868878 | D20: =IF('Profit & Loss'!D4>0,'Balance Sheet'!D17/('Profit & Loss'!D4/365),0) -> 30.834031 | E20: =IF('Profit & Loss'!E4>0,'Balance Sheet'!E17/('Profit & Loss'!E4/365),0) -> 22.424856 | F20: =IF('Profit & Loss'!F4>0,'Balance Sheet'!F17/('Profit & Loss'!F4/365),0) -> 20.508649 | G20: =IF('Profit & Loss'!G4>0,'Balance Sheet'!G17/('Profit & Loss'!G4/365),0) -> 18.595248 | H20: =IF('Profit & Loss'!H4>0,'Balance Sheet'!H17/('Profit & Loss'!H4/365),0) -> 15.689986 | I20: =IF('Profit & Loss'!I4>0,'Balance Sheet'!I17/('Profit & Loss'!I4/365),0) -> 15.742432 | ... K20: =IF('Profit & Loss'!K4>0,'Balance Sheet'!K17/('Profit & Loss'!K4/365),0) -> 22.159379
A21: Inventory Turnover | B21: =IF('Balance Sheet'!B18>0,'Profit & Loss'!B4/'Balance Sheet'!B18,0) -> 4.8796841 | C21: =IF('Balance Sheet'!C18>0,'Profit & Loss'!C4/'Balance Sheet'!C18,0) -> 5.7116881 | D21: =IF('Balance Sheet'!D18>0,'Profit & Loss'!D4/'Balance Sheet'!D18,0) -> 5.8260242 | E21: =IF('Balance Sheet'!E18>0,'Profit & Loss'!E4/'Balance Sheet'!E18,0) -> 5.3238946 | F21: =IF('Balance Sheet'!F18>0,'Profit & Loss'!F4/'Balance Sheet'!F18,0) -> 5.60313 | G21: =IF('Balance Sheet'!G18>0,'Profit & Loss'!G4/'Balance Sheet'!G18,0) -> 4.3321692 | H21: =IF('Balance Sheet'!H18>0,'Profit & Loss'!H4/'Balance Sheet'!H18,0) -> 5.0086012 | I21: =IF('Balance Sheet'!I18>0,'Profit & Loss'!I4/'Balance Sheet'!I18,0) -> 4.6279519 | ... K21: =IF('Balance Sheet'!K18>0,'Profit & Loss'!K4/'Balance Sheet'!K18,0) -> 5.6606135
A23: Return on Equity | B23: =IF(SUM('Balance Sheet'!B4:B5)>0,'Profit & Loss'!B12/SUM('Balance Sheet'!B4:B5),"") -> 0.15556144 | C23: =IF(SUM('Balance Sheet'!C4:C5)>0,'Profit & Loss'!C12/SUM('Balance Sheet'!C4:C5),"") -> 0.22194442 | D23: =IF(SUM('Balance Sheet'!D4:D5)>0,'Profit & Loss'!D12/SUM('Balance Sheet'!D4:D5),"") -> 0.21954304 | E23: =IF(SUM('Balance Sheet'!E4:E5)>0,'Profit & Loss'!E12/SUM('Balance Sheet'!E4:E5),"") -> 0.1101123 | F23: =IF(SUM('Balance Sheet'!F4:F5)>0,'Profit & Loss'!F12/SUM('Balance Sheet'!F4:F5),"") -> 0.17344881 | G23: =IF(SUM('Balance Sheet'!G4:G5)>0,'Profit & Loss'!G12/SUM('Balance Sheet'!G4:G5),"") -> 0.30707164 | H23: =IF(SUM('Balance Sheet'!H4:H5)>0,'Profit & Loss'!H12/SUM('Balance Sheet'!H4:H5),"") -> 0.063079382 | I23: =IF(SUM('Balance Sheet'!I4:I5)>0,'Profit & Loss'!I12/SUM('Balance Sheet'!I4:I5),"") -> 0.11345582 | ... K23: =IF(SUM('Balance Sheet'!K4:K5)>0,'Profit & Loss'!K12/SUM('Balance Sheet'!K4:K5),"") -> 0.22304179
A24: Return on Capital Emp | C24: =IF((B4+B5+B6+C4+C5+C6)>0,('Profit & Loss'!C10+'Profit & Loss'!C9)*2/(B4+B5+B6+C4+C5+C6),"") -> 0.17023063 | D24: =IF((C4+C5+C6+D4+D5+D6)>0,('Profit & Loss'!D10+'Profit & Loss'!D9)*2/(C4+C5+C6+D4+D5+D6),"") -> 0.20169539 | E24: =IF((D4+D5+D6+E4+E5+E6)>0,('Profit & Loss'!E10+'Profit & Loss'!E9)*2/(D4+D5+D6+E4+E5+E6),"") -> 0.080771088 | F24: =IF((E4+E5+E6+F4+F5+F6)>0,('Profit & Loss'!F10+'Profit & Loss'!F9)*2/(E4+E5+E6+F4+F5+F6),"") -> 0.15185469 | G24: =IF((F4+F5+F6+G4+G5+G6)>0,('Profit & Loss'!G10+'Profit & Loss'!G9)*2/(F4+F5+F6+G4+G5+G6),"") -> 0.2756411 | H24: =IF((G4+G5+G6+H4+H5+H6)>0,('Profit & Loss'!H10+'Profit & Loss'!H9)*2/(G4+G5+G6+H4+H5+H6),"") -> 0.087786019 | I24: =IF((H4+H5+H6+I4+I5+I6)>0,('Profit & Loss'!I10+'Profit & Loss'!I9)*2/(H4+H5+H6+I4+I5+I6),"") -> 0.13763569 | J24: =IF((I4+I5+I6+J4+J5+J6)>0,('Profit & Loss'!J10+'Profit & Loss'!J9)*2/(I4+I5+I6+J4+J5+J6),"") -> 0.078446995 | K24: =IF((J4+J5+J6+K4+K5+K6)>0,('Profit & Loss'!K10+'Profit & Loss'!K9)*2/(J4+J5+J6+K4+K5+K6),"") -> 0.20312968

Sheet Cash Flow
A1: ='Balance Sheet'!A1 -> JSW STEEL LTD | E1: =UPDATE -> JSW STEEL LTD | J1: SCREENER.IN
A3: Narration | B3: ='Data Sheet'!B81 -> 42825 | C3: ='Data Sheet'!C81 -> 43190 | D3: ='Data Sheet'!D81 -> 43555 | E3: ='Data Sheet'!E81 -> 43921 | F3: ='Data Sheet'!F81 -> 44286 | G3: ='Data Sheet'!G81 -> 44651 | H3: ='Data Sheet'!H81 -> 45016 | I3: ='Data Sheet'!I81 -> 45382 | ... K3: ='Data Sheet'!K81 -> 46112
A4: Cash from Operating Activity | B4: ='Data Sheet'!B82 -> 7888 | C4: ='Data Sheet'!C82 -> 12379 | D4: ='Data Sheet'!D82 -> 14633 | E4: ='Data Sheet'!E82 -> 12785 | F4: ='Data Sheet'!F82 -> 18831 | G4: ='Data Sheet'!G82 -> 26270 | H4: ='Data Sheet'!H82 -> 23323 | I4: ='Data Sheet'!I82 -> 12078 | ... K4: ='Data Sheet'!K82 -> 25152
A5: Cash from Investing Activity | B5: ='Data Sheet'!B83 -> -5094 | C5: ='Data Sheet'!C83 -> -4529 | D5: ='Data Sheet'!D83 -> -11387 | E5: ='Data Sheet'!E83 -> -19589 | F5: ='Data Sheet'!F83 -> -9410 | G5: ='Data Sheet'!G83 -> -14748 | H5: ='Data Sheet'!H83 -> -10730 | I5: ='Data Sheet'!I83 -> -14467 | ... K5: ='Data Sheet'!K83 -> 18690
A6: Cash from Financing Activity | B6: ='Data Sheet'!B84 -> -2710 | C6: ='Data Sheet'!C84 -> -8185 | D6: ='Data Sheet'!D84 -> 1753 | E6: ='Data Sheet'!E84 -> 5189 | F6: ='Data Sheet'!F84 -> -1444 | G6: ='Data Sheet'!G84 -> -14657 | H6: ='Data Sheet'!H84 -> -5977 | I6: ='Data Sheet'!I84 -> -5005 | ... K6: ='Data Sheet'!K84 -> -16111
A7: Net Cash Flow | B7: ='Data Sheet'!B85 -> 84 | C7: ='Data Sheet'!C85 -> -335 | D7: ='Data Sheet'!D85 -> 4999 | E7: ='Data Sheet'!E85 -> -1615 | F7: ='Data Sheet'!F85 -> 7977 | G7: ='Data Sheet'!G85 -> -3135 | H7: ='Data Sheet'!H85 -> 6616 | I7: ='Data Sheet'!I85 -> -7394 | ... K7: ='Data Sheet'!K85 -> 27731

Sheet Customization
A1: How to use it?
A3: You can customize this workbook as you want.
B4: You can add custom formating, add conditional formating, add your own formulas… do ANYTHING.
B5: Please don't edit the "Data Sheet" only.
A7: After customization, you can upload this back on Screener.
B8: Upload on: | C8: https://www.screener.in/excel/
A10: Download your customized workbooks now onwards.
B11: Now whenever you will "Export to excel" from Screener, it will export your customized file.
A14: TESTING:
B15: This is a testing feature currently.
B16: You can report any formula errors on the worksheet at: support@screener.in

Sheet Historical
B2: ="Financial Statement - "&'Data Sheet'!B1 -> Financial Statement - JSW STEEL LTD
B4: Particulars | C4: ='Data Sheet'!B16 -> 42825 | D4: ='Data Sheet'!C16 -> 43190 | E4: ='Data Sheet'!D16 -> 43555 | F4: ='Data Sheet'!E16 -> 43921 | G4: ='Data Sheet'!F16 -> 44286 | H4: ='Data Sheet'!G16 -> 44651 | I4: ='Data Sheet'!H16 -> 45016 | J4: ='Data Sheet'!I16 -> 45382 | ... L4: ='Data Sheet'!K16 -> 46112 | M4: LTM
A5: # | B5: income statement
B7: sales | C7: ='Data Sheet'!B17 -> 55604 | D7: ='Data Sheet'!C17 -> 71933 | E7: ='Data Sheet'!D17 -> 84757 | F7: ='Data Sheet'!E17 -> 73326 | G7: ='Data Sheet'!F17 -> 79839 | H7: ='Data Sheet'!G17 -> 146371 | I7: ='Data Sheet'!H17 -> 165960 | J7: ='Data Sheet'!I17 -> 175006 | ... L7: ='Data Sheet'!K17 -> 185470 | M7: =IFERROR(SUM('Data Sheet'!H42:K42),0) -> 185470
B8: sales growth | D8: =D7/C7-1 -> 0.29366592 | E8: =E7/D7-1 -> 0.17827701 | F8: =F7/E7-1 -> -0.13486792 | G8: =G7/F7-1 -> 0.088822519 | H8: =H7/G7-1 -> 0.83332707 | I8: =I7/H7-1 -> 0.13383116 | J8: =J7/I7-1 -> 0.05450711 | K8: =K7/J7-1 -> -0.035324503 | ... M8: =M7/L7-1 -> 0
B10: COGS | C10: =IFERROR(SUM('Data Sheet'!B18,'Data Sheet'!B20:B22)-1*'Data Sheet'!B19,0) -> 41733 | D10: =IFERROR(SUM('Data Sheet'!C18,'Data Sheet'!C20:C22)-1*'Data Sheet'!C19,0) -> 55278 | E10: =IFERROR(SUM('Data Sheet'!D18,'Data Sheet'!D20:D22)-1*'Data Sheet'!D19,0) -> 62906 | F10: =IFERROR(SUM('Data Sheet'!E18,'Data Sheet'!E20:E22)-1*'Data Sheet'!E19,0) -> 58084 | G10: =IFERROR(SUM('Data Sheet'!F18,'Data Sheet'!F20:F22)-1*'Data Sheet'!F19,0) -> 57246 | H10: =IFERROR(SUM('Data Sheet'!G18,'Data Sheet'!G20:G22)-1*'Data Sheet'!G19,0) -> 103778 | I10: =IFERROR(SUM('Data Sheet'!H18,'Data Sheet'!H20:H22)-1*'Data Sheet'!H19,0) -> 140925 | J10: =IFERROR(SUM('Data Sheet'!I18,'Data Sheet'!I20:I22)-1*'Data Sheet'!I19,0) -> 141101 | ... L10: =IFERROR(SUM('Data Sheet'!K18,'Data Sheet'!K20:K22)-1*'Data Sheet'!K19,0) -> 118028 | M10: =IFERROR(SUM('Data Sheet'!H43:K43),0) -> 156124
B11: cogs % sales | C11: =C10/C7 -> 0.75053953 | D11: =D10/D7 -> 0.7684651 | E11: =E10/E7 -> 0.74219239 | F11: =F10/F7 -> 0.79213376 | G11: =G10/G7 -> 0.717018 | H11: =H10/H7 -> 0.70900657 | I11: =I10/I7 -> 0.8491504 | J11: =J10/J7 -> 0.80626379 | ... M11: =M10/M7 -> 0.84177495
B13: gross profit | C13: =IFERROR(SUM(C7)-C10,0) -> 13871 | D13: =IFERROR(SUM(D7)-D10,0) -> 16655 | E13: =IFERROR(SUM(E7)-E10,0) -> 21851 | F13: =IFERROR(SUM(F7)-F10,0) -> 15242 | G13: =IFERROR(SUM(G7)-G10,0) -> 22593 | H13: =IFERROR(SUM(H7)-H10,0) -> 42593 | I13: =IFERROR(SUM(I7)-I10,0) -> 25035 | J13: =IFERROR(SUM(J7)-J10,0) -> 33905 | ... M13: =IFERROR(SUM(M7)-M10,0) -> 29346
B14: gross profit as % sales | C14: =C13/C7 -> 0.24946047 | D14: =D13/D7 -> 0.2315349 | E14: =E13/E7 -> 0.25780761 | F14: =F13/F7 -> 0.20786624 | G14: =G13/G7 -> 0.282982 | H14: =H13/H7 -> 0.29099343 | I14: =I13/I7 -> 0.1508496 | J14: =J13/J7 -> 0.19373621 | ... M14: =M13/M7 -> 0.15822505
B16: SG&A | C16: =IFERROR(SUM('Data Sheet'!B23,'Data Sheet'!B24),0) -> 1563 | D16: =IFERROR(SUM('Data Sheet'!C23,'Data Sheet'!C24),0) -> 1739 | E16: =IFERROR(SUM('Data Sheet'!D23,'Data Sheet'!D24),0) -> 2921 | F16: =IFERROR(SUM('Data Sheet'!E23,'Data Sheet'!E24),0) -> 3429 | G16: =IFERROR(SUM('Data Sheet'!F23,'Data Sheet'!F24),0) -> 2415 | H16: =IFERROR(SUM('Data Sheet'!G23,'Data Sheet'!G24),0) -> 3479 | I16: =IFERROR(SUM('Data Sheet'!H23,'Data Sheet'!H24),0) -> 6565 | J16: =IFERROR(SUM('Data Sheet'!I23,'Data Sheet'!I24),0) -> 5748 | ... L16: =IFERROR(SUM('Data Sheet'!K23,'Data Sheet'!K24),0) -> 38096 | M16: =IFERROR(SUM('Data Sheet'!B23,'Data Sheet'!B24),0) -> 1563
B17: SG&A as % of sales | C17: =C16/C7 -> 0.028109489 | D17: =D16/D7 -> 0.024175274 | E17: =E16/E7 -> 0.03446323 | F17: =F16/F7 -> 0.046763767 | G17: =G16/G7 -> 0.030248375 | H17: =H16/H7 -> 0.023768369 | I17: =I16/I7 -> 0.039557725 | J17: =J16/J7 -> 0.032844588 | ... M17: =M16/M7 -> 0.0084272389
B19: EBITDA | C19: =IFERROR(C13-C16,0) -> 12308 | D19: =IFERROR(D13-D16,0) -> 14916 | E19: =IFERROR(E13-E16,0) -> 18930 | F19: =IFERROR(F13-F16,0) -> 11813 | G19: =IFERROR(G13-G16,0) -> 20178 | H19: =IFERROR(H13-H16,0) -> 39114 | I19: =IFERROR(I13-I16,0) -> 18470 | J19: =IFERROR(J13-J16,0) -> 28157 | ... M19: =IFERROR(M13-M16,0) -> 27783
B20: ebitda as % of sales | C20: =C19/C7 -> 0.22135098 | D20: =D19/D7 -> 0.20735963 | E20: =E19/E7 -> 0.22334438 | F20: =F19/F7 -> 0.16110247 | G20: =G19/G7 -> 0.25273363 | H20: =H19/H7 -> 0.26722507 | I20: =I19/I7 -> 0.11129188 | J20: =J19/J7 -> 0.16089163 | ... M20: =M19/M7 -> 0.14979781
B22: Interest | C22: =IFERROR('Data Sheet'!B27,0) -> 3768 | D22: =IFERROR('Data Sheet'!C27,0) -> 3701 | E22: =IFERROR('Data Sheet'!D27,0) -> 3917 | F22: =IFERROR('Data Sheet'!E27,0) -> 4265 | G22: =IFERROR('Data Sheet'!F27,0) -> 3957 | H22: =IFERROR('Data Sheet'!G27,0) -> 4968 | I22: =IFERROR('Data Sheet'!H27,0) -> 6902 | J22: =IFERROR('Data Sheet'!I27,0) -> 8105 | ... L22: =IFERROR('Data Sheet'!K27,0) -> 9102 | M22: =IFERROR(SUM('Data Sheet'!H46:K46),0) -> 9102
B23: interset as % of sale | C23: =C22/C7 -> 0.067764909 | D23: =D22/D7 -> 0.051450655 | E23: =E22/E7 -> 0.046214472 | F23: =F22/F7 -> 0.058164907 | G23: =G22/G7 -> 0.049562244 | H23: =H22/H7 -> 0.03394115 | I23: =I22/I7 -> 0.041588335 | J23: =J22/J7 -> 0.046312698 | ... M23: =M22/M7 -> 0.049075322
B25: Depriciation | C25: =IFERROR('Data Sheet'!B26,0) -> 3430 | D25: =IFERROR('Data Sheet'!C26,0) -> 3387 | E25: =IFERROR('Data Sheet'!D26,0) -> 4041 | F25: =IFERROR('Data Sheet'!E26,0) -> 4246 | G25: =IFERROR('Data Sheet'!F26,0) -> 4679 | H25: =IFERROR('Data Sheet'!G26,0) -> 6001 | I25: =IFERROR('Data Sheet'!H26,0) -> 7474 | J25: =IFERROR('Data Sheet'!I26,0) -> 8172 | ... L25: =IFERROR('Data Sheet'!K26,0) -> 9601 | M25: =IFERROR(SUM('Data Sheet'!H45:K45),0) -> 9601
B26: depriciation % of slaes | C26: =C25/C7 -> 0.06168621 | D26: =D25/D7 -> 0.047085482 | E26: =E25/E7 -> 0.047677478 | F26: =F25/F7 -> 0.057905791 | G26: =G25/G7 -> 0.058605443 | H26: =H25/H7 -> 0.040998558 | I26: =I25/I7 -> 0.045034948 | J26: =J25/J7 -> 0.046695542 | ... M26: =M25/M7 -> 0.051765784
B28: EBT | C28: =IFERROR(C19-C22-C25,0) -> 5110 | D28: =IFERROR(D19-D22-D25,0) -> 7828 | E28: =IFERROR(E19-E22-E25,0) -> 10972 | F28: =IFERROR(F19-F22-F25,0) -> 3302 | G28: =IFERROR(G19-G22-G25,0) -> 11542 | H28: =IFERROR(H19-H22-H25,0) -> 28145 | I28: =IFERROR(I19-I22-I25,0) -> 4094 | J28: =IFERROR(J19-J22-J25,0) -> 11880 | ... M28: =IFERROR(M19-M22-M25,0) -> 9080
B29: ebt % of sales | C29: =C28/C7 -> 0.091899863 | D29: =D28/D7 -> 0.10882349 | E29: =E28/E7 -> 0.12945243 | F29: =F28/F7 -> 0.045031776 | G29: =G28/G7 -> 0.14456594 | H29: =H28/H7 -> 0.19228536 | I29: =I28/I7 -> 0.024668595 | J29: =J28/J7 -> 0.067883387 | ... L29: =L28/L7 -> 0.057383943
B31: TAX | C31: =IFERROR('Data Sheet'!B29,0) -> 1674 | D31: =IFERROR('Data Sheet'!C29,0) -> 1538 | E31: =IFERROR('Data Sheet'!D29,0) -> 3644 | F31: =IFERROR('Data Sheet'!E29,0) -> -906 | G31: =IFERROR('Data Sheet'!F29,0) -> 4142 | H31: =IFERROR('Data Sheet'!G29,0) -> 8807 | I31: =IFERROR('Data Sheet'!H29,0) -> 1516 | J31: =IFERROR('Data Sheet'!I29,0) -> 4407 | ... L31: =IFERROR('Data Sheet'!K29,0) -> 3742 | M31: =IFERROR(SUM('Data Sheet'!H48:K48),0) -> 3742
B32: effective tax rate % of EBT | C32: =C31/C28 -> 0.32759295 | D32: =D31/D28 -> 0.1964742 | E32: =E31/E28 -> 0.33211812 | F32: =F31/F28 -> -0.27437916 | G32: =G31/G28 -> 0.35886328 | H32: =H31/H28 -> 0.31291526 | I32: =I31/I28 -> 0.370298 | J32: =J31/J28 -> 0.3709596 | ... M32: =M31/M28 -> 0.41211454
B34: Net Profit | C34: =IFERROR(C28-C31,0) -> 3436 | D34: =IFERROR(D28-D31,0) -> 6290 | E34: =IFERROR(E28-E31,0) -> 7328 | F34: =IFERROR(F28-F31,0) -> 4208 | G34: =IFERROR(G28-G31,0) -> 7400 | H34: =IFERROR(H28-H31,0) -> 19338 | I34: =IFERROR(I28-I31,0) -> 2578 | J34: =IFERROR(J28-J31,0) -> 7473 | ... M34: =IFERROR(M28-M31,0) -> 5338
B35: net margin | C35: =C34/C7 -> 0.061794116 | D35: =D34/D7 -> 0.087442481 | E35: =E34/E7 -> 0.086458936 | F35: =F34/F7 -> 0.057387557 | G35: =G34/G7 -> 0.092686532 | H35: =H34/H7 -> 0.13211633 | I35: =I34/I7 -> 0.015533864 | J35: =J34/J7 -> 0.042701393 | ... M35: =M34/M7 -> 0.028780935
B37: Adjusted Equity Shares in Cr | C37: 288.72 | D37: 288.73 | E37: 288.73 | F37: 288.73 | G37: 308.9 | H37: 332.03 | I37: 332.07 | J37: 332.13 | K37: 332.37 | L37: 368.13
B39: EPS | C39: =IFERROR(C34/C37,0) -> 11.900804 | D39: =IFERROR(D34/D37,0) -> 21.785059 | E39: =IFERROR(E34/E37,0) -> 25.380113 | F39: =IFERROR(F34/F37,0) -> 14.57417 | G39: =IFERROR(G34/G37,0) -> 23.955973 | H39: =IFERROR(H34/H37,0) -> 58.241725 | I39: =IFERROR(I34/I37,0) -> 7.7634234 | J39: =IFERROR(J34/J37,0) -> 22.500226 | ... L39: =IFERROR(L34/L37,0) -> 18.746095
B40: eps growth % | D40: =IFERROR(D39/C39-1,0) -> 0.83055359 | E40: =IFERROR(E39/D39-1,0) -> 0.16502385 | F40: =IFERROR(F39/E39-1,0) -> -0.42576419 | G40: =IFERROR(G39/F39-1,0) -> 0.64372814 | H40: =IFERROR(H39/G39-1,0) -> 1.4311985 | I40: =IFERROR(I39/H39-1,0) -> -0.86670341 | J40: =IFERROR(J39/I39-1,0) -> 1.8982351 | K40: =IFERROR(K39/J39-1,0) -> -0.54295037 | L40: =IFERROR(L39/K39-1,0) -> 0.82289047
B42: dividend per share | C42: =IFERROR('Data Sheet'!B31/C37,0) -> 2.3456983 | D42: =IFERROR('Data Sheet'!C31/D37,0) -> 3.3470717 | E42: =IFERROR('Data Sheet'!D31/E37,0) -> 4.2742354 | F42: =IFERROR('Data Sheet'!E31/F37,0) -> 2.0849929 | G42: =IFERROR('Data Sheet'!F31/G37,0) -> 6.3548074 | H42: =IFERROR('Data Sheet'!G31/H37,0) -> 15.728549 | I42: =IFERROR('Data Sheet'!H31/I37,0) -> 3.0818803 | J42: =IFERROR('Data Sheet'!I31/J37,0) -> 6.7037004 | ... L42: =IFERROR('Data Sheet'!K31/L37,0) -> 5.8824328
B43: dividend payout ratio % | C43: =IFERROR(C42/C39,0) -> 0.19710419 | D43: =IFERROR(D42/D39,0) -> 0.1536407 | E43: =IFERROR(E42/E39,0) -> 0.16840884 | F43: =IFERROR(F42/F39,0) -> 0.14306084 | G43: =IFERROR(G42/G39,0) -> 0.26527027 | H43: =IFERROR(H42/H39,0) -> 0.27005637 | I43: =IFERROR(I42/I39,0) -> 0.3969744 | J43: =IFERROR(J42/J39,0) -> 0.29793925 | ... L43: =IFERROR(L42/L39,0) -> 0.3137951
B45: retained earning | C45: =IFERROR(IF(C39>C42,1-C43,0),0) -> 0.80289581 | D45: =IFERROR(IF(D39>D42,1-D43,0),0) -> 0.8463593 | E45: =IFERROR(IF(E39>E42,1-E43,0),0) -> 0.83159116 | F45: =IFERROR(IF(F39>F42,1-F43,0),0) -> 0.85693916 | G45: =IFERROR(IF(G39>G42,1-G43,0),0) -> 0.73472973 | H45: =IFERROR(IF(H39>H42,1-H43,0),0) -> 0.72994363 | I45: =IFERROR(IF(I39>I42,1-I43,0),0) -> 0.6030256 | J45: =IFERROR(IF(J39>J42,1-J43,0),0) -> 0.70206075 | ... L45: =IFERROR(IF(L39>L42,1-L43,0),0) -> 0.6862049
A50: # | B50: balance sheet
B52: Equity Share Capital | C52: =IFERROR('Data Sheet'!B57,0) -> 301 | D52: =IFERROR('Data Sheet'!C57,0) -> 302 | E52: =IFERROR('Data Sheet'!D57,0) -> 301 | F52: =IFERROR('Data Sheet'!E57,0) -> 301 | G52: =IFERROR('Data Sheet'!F57,0) -> 302 | H52: =IFERROR('Data Sheet'!G57,0) -> 301 | I52: =IFERROR('Data Sheet'!H57,0) -> 301 | J52: =IFERROR('Data Sheet'!I57,0) -> 305 | ... L52: =IFERROR('Data Sheet'!K57,0) -> 305
B53: Reserves | C53: =IFERROR('Data Sheet'!B58,0) -> 22346 | D53: =IFERROR('Data Sheet'!C58,0) -> 27696 | E53: =IFERROR('Data Sheet'!D58,0) -> 34494 | F53: =IFERROR('Data Sheet'!E58,0) -> 36298 | G53: =IFERROR('Data Sheet'!F58,0) -> 45308 | H53: =IFERROR('Data Sheet'!G58,0) -> 66996 | I53: =IFERROR('Data Sheet'!H58,0) -> 65394 | J53: =IFERROR('Data Sheet'!I58,0) -> 77364 | ... L53: =IFERROR('Data Sheet'!K58,0) -> 99748
B54: Borrowings | C54: =IFERROR('Data Sheet'!B59,0) -> 43334 | D54: =IFERROR('Data Sheet'!C59,0) -> 39393 | E54: =IFERROR('Data Sheet'!D59,0) -> 47396 | F54: =IFERROR('Data Sheet'!E59,0) -> 61423 | G54: =IFERROR('Data Sheet'!F59,0) -> 66727 | H54: =IFERROR('Data Sheet'!G59,0) -> 72237 | I54: =IFERROR('Data Sheet'!H59,0) -> 80853 | J54: =IFERROR('Data Sheet'!I59,0) -> 87984 | ... L54: =IFERROR('Data Sheet'!K59,0) -> 99310
B55: Other Liabilities | C55: =IFERROR('Data Sheet'!B60,0) -> 22024 | D55: =IFERROR('Data Sheet'!C60,0) -> 24579 | E55: =IFERROR('Data Sheet'!D60,0) -> 32606 | F55: =IFERROR('Data Sheet'!E60,0) -> 33798 | G55: =IFERROR('Data Sheet'!F60,0) -> 34826 | H55: =IFERROR('Data Sheet'!G60,0) -> 56951 | I55: =IFERROR('Data Sheet'!H60,0) -> 63991 | J55: =IFERROR('Data Sheet'!I60,0) -> 62245 | ... L55: =IFERROR('Data Sheet'!K60,0) -> 70313
B56: total libalitites | C56: =IFERROR('Data Sheet'!B61,0) -> 88005 | D56: =IFERROR('Data Sheet'!C61,0) -> 91970 | E56: =IFERROR('Data Sheet'!D61,0) -> 114797 | F56: =IFERROR('Data Sheet'!E61,0) -> 131820 | G56: =IFERROR('Data Sheet'!F61,0) -> 147163 | H56: =IFERROR('Data Sheet'!G61,0) -> 196485 | I56: =IFERROR('Data Sheet'!H61,0) -> 210539 | J56: =IFERROR('Data Sheet'!I61,0) -> 227898 | ... L56: =IFERROR('Data Sheet'!K61,0) -> 269676
B58: assest net block | C58: =IFERROR('Data Sheet'!B62,0) -> 58730 | D58: =IFERROR('Data Sheet'!C62,0) -> 57848 | E58: =IFERROR('Data Sheet'!D62,0) -> 62644 | F58: =IFERROR('Data Sheet'!E62,0) -> 62085 | G58: =IFERROR('Data Sheet'!F62,0) -> 64917 | H58: =IFERROR('Data Sheet'!G62,0) -> 99880 | I58: =IFERROR('Data Sheet'!H62,0) -> 104452 | J58: =IFERROR('Data Sheet'!I62,0) -> 112461 | ... L58: =IFERROR('Data Sheet'!K62,0) -> 117552
B59: Capital Work in Progress | C59: =IFERROR('Data Sheet'!B63,0) -> 4363 | D59: =IFERROR('Data Sheet'!C63,0) -> 5950 | E59: =IFERROR('Data Sheet'!D63,0) -> 11889 | F59: =IFERROR('Data Sheet'!E63,0) -> 27191 | G59: =IFERROR('Data Sheet'!F63,0) -> 32566 | H59: =IFERROR('Data Sheet'!G63,0) -> 16905 | I59: =IFERROR('Data Sheet'!H63,0) -> 22166 | J59: =IFERROR('Data Sheet'!I63,0) -> 29676 | ... L59: =IFERROR('Data Sheet'!K63,0) -> 21892
B60: Investments | C60: =IFERROR('Data Sheet'!B64,0) -> 1366 | D60: =IFERROR('Data Sheet'!C64,0) -> 1469 | E60: =IFERROR('Data Sheet'!D64,0) -> 1894 | F60: =IFERROR('Data Sheet'!E64,0) -> 1259 | G60: =IFERROR('Data Sheet'!F64,0) -> 7427 | H60: =IFERROR('Data Sheet'!G64,0) -> 4940 | I60: =IFERROR('Data Sheet'!H64,0) -> 4806 | J60: =IFERROR('Data Sheet'!I64,0) -> 7246 | ... L60: =IFERROR('Data Sheet'!K64,0) -> 10218
B61: Other Assets | C61: =IFERROR('Data Sheet'!B65-SUM('Data Sheet'!B67:B69),0) -> 6517 | D61: =IFERROR('Data Sheet'!C65-SUM('Data Sheet'!C67:C69),0) -> 8342 | E61: =IFERROR('Data Sheet'!D65-SUM('Data Sheet'!D67:D69),0) -> 10475 | F61: =IFERROR('Data Sheet'!E65-SUM('Data Sheet'!E67:E69),0) -> 11004 | G61: =IFERROR('Data Sheet'!F65-SUM('Data Sheet'!F67:F69),0) -> 10705 | H61: =IFERROR('Data Sheet'!G65-SUM('Data Sheet'!G67:G69),0) -> 16133 | I61: =IFERROR('Data Sheet'!H65-SUM('Data Sheet'!H67:H69),0) -> 18132 | J61: =IFERROR('Data Sheet'!I65-SUM('Data Sheet'!I67:I69),0) -> 20804 | ... L61: =IFERROR('Data Sheet'!K65-SUM('Data Sheet'!K67:K69),0) -> 35000
B62: total non current assest | C62: =IFERROR(SUM(C58:C61),0) -> 70976 | D62: =IFERROR(SUM(D58:D61),0) -> 73609 | E62: =IFERROR(SUM(E58:E61),0) -> 86902 | F62: =IFERROR(SUM(F58:F61),0) -> 101539 | G62: =IFERROR(SUM(G58:G61),0) -> 115615 | H62: =IFERROR(SUM(H58:H61),0) -> 137858 | I62: =IFERROR(SUM(I58:I61),0) -> 149556 | J62: =IFERROR(SUM(J58:J61),0) -> 170187 | ... L62: =IFERROR(SUM(L58:L61),0) -> 184662
...

Sheet Common Size
B2: Common Size Statement
B5: Particulars | F5: ='Data Sheet'!B16 -> 42825 | G5: ='Data Sheet'!C16 -> 43190 | H5: ='Data Sheet'!D16 -> 43555 | I5: ='Data Sheet'!E16 -> 43921 | J5: ='Data Sheet'!F16 -> 44286 | K5: ='Data Sheet'!G16 -> 44651 | L5: ='Data Sheet'!H16 -> 45016 | M5: ='Data Sheet'!I16 -> 45382 | ... O5: ='Data Sheet'!K16 -> 46112
A6: # | B6: Income Statement
B8: ='Data Sheet'!A17 -> Sales | F8: ='Data Sheet'!B17/'Data Sheet'!B$17 -> 1 | G8: ='Data Sheet'!C17/'Data Sheet'!C$17 -> 1 | H8: ='Data Sheet'!D17/'Data Sheet'!D$17 -> 1 | I8: ='Data Sheet'!E17/'Data Sheet'!E$17 -> 1 | J8: ='Data Sheet'!F17/'Data Sheet'!F$17 -> 1 | K8: ='Data Sheet'!G17/'Data Sheet'!G$17 -> 1 | L8: ='Data Sheet'!H17/'Data Sheet'!H$17 -> 1 | M8: ='Data Sheet'!I17/'Data Sheet'!I$17 -> 1 | ... O8: ='Data Sheet'!K17/'Data Sheet'!K$17 -> 1
B9: ='Data Sheet'!A18 -> Raw Material Cost | F9: ='Data Sheet'!B18/'Data Sheet'!B$17 -> 0.53501547 | G9: ='Data Sheet'!C18/'Data Sheet'!C$17 -> 0.53912669 | H9: ='Data Sheet'!D18/'Data Sheet'!D$17 -> 0.51672428 | I9: ='Data Sheet'!E18/'Data Sheet'!E$17 -> 0.53187137 | J9: ='Data Sheet'!F18/'Data Sheet'!F$17 -> 0.4115282 | K9: ='Data Sheet'!G18/'Data Sheet'!G$17 -> 0.42953181 | L9: ='Data Sheet'!H18/'Data Sheet'!H$17 -> 0.57827187 | M9: ='Data Sheet'!I18/'Data Sheet'!I$17 -> 0.54143287 | ... O9: ='Data Sheet'!K18/'Data Sheet'!K$17 -> 0.49534696
B10: ='Data Sheet'!A19 -> Change in Inventory | F10: ='Data Sheet'!B19/'Data Sheet'!B$17 -> 0.026724696 | G10: ='Data Sheet'!C19/'Data Sheet'!C$17 -> -0.0033920454 | H10: ='Data Sheet'!D19/'Data Sheet'!D$17 -> 0.006961077 | I10: ='Data Sheet'!E19/'Data Sheet'!E$17 -> 0.0036821864 | J10: ='Data Sheet'!F19/'Data Sheet'!F$17 -> 0.004358772 | K10: ='Data Sheet'!G19/'Data Sheet'!G$17 -> 0.024601868 | L10: ='Data Sheet'!H19/'Data Sheet'!H$17 -> 0.015883345 | M10: ='Data Sheet'!I19/'Data Sheet'!I$17 -> 0.017639395 | ... O10: ='Data Sheet'!K19/'Data Sheet'!K$17 -> -0.025443468
B11: ='Data Sheet'!A20 -> Power and Fuel | F11: ='Data Sheet'!B20/'Data Sheet'!B$17 -> 0.087817423 | G11: ='Data Sheet'!C20/'Data Sheet'!C$17 -> 0.079198699 | H11: ='Data Sheet'!D20/'Data Sheet'!D$17 -> 0.083214366 | I11: ='Data Sheet'!E20/'Data Sheet'!E$17 -> 0.085535826 | J11: ='Data Sheet'!F20/'Data Sheet'!F$17 -> 0.074963364 | K11: ='Data Sheet'!G20/'Data Sheet'!G$17 -> 0.077125933 | L11: ='Data Sheet'!H20/'Data Sheet'!H$17 -> 0.10515787 | M11: ='Data Sheet'!I20/'Data Sheet'!I$17 -> 0.086437036 | ... O11: ='Data Sheet'!K20/'Data Sheet'!K$17 -> 0.08708686
B12: ='Data Sheet'!A21 -> Other Mfr. Exp | F12: ='Data Sheet'!B21/'Data Sheet'!B$17 -> 0.123858 | G12: ='Data Sheet'!C21/'Data Sheet'!C$17 -> 0.1211266 | H12: ='Data Sheet'!D21/'Data Sheet'!D$17 -> 0.11984851 | I12: ='Data Sheet'!E21/'Data Sheet'!E$17 -> 0.13969124 | J12: ='Data Sheet'!F21/'Data Sheet'!F$17 -> 0.20349704 | K12: ='Data Sheet'!G21/'Data Sheet'!G$17 -> 0.20308668 | L12: ='Data Sheet'!H21/'Data Sheet'!H$17 -> 0.15801398 | M12: ='Data Sheet'!I21/'Data Sheet'!I$17 -> 0.16979989 | ... O12: ='Data Sheet'!K21/'Data Sheet'!K$17 -> 0
B13: ='Data Sheet'!A22 -> Employee Cost | F13: ='Data Sheet'!B22/'Data Sheet'!B$17 -> 0.03057334 | G13: ='Data Sheet'!C22/'Data Sheet'!C$17 -> 0.025621064 | H13: ='Data Sheet'!D22/'Data Sheet'!D$17 -> 0.029366306 | I13: ='Data Sheet'!E22/'Data Sheet'!E$17 -> 0.038717508 | J13: ='Data Sheet'!F22/'Data Sheet'!F$17 -> 0.031388169 | K13: ='Data Sheet'!G22/'Data Sheet'!G$17 -> 0.023864017 | L13: ='Data Sheet'!H22/'Data Sheet'!H$17 -> 0.023590022 | M13: ='Data Sheet'!I22/'Data Sheet'!I$17 -> 0.026233386 | ... O13: ='Data Sheet'!K22/'Data Sheet'!K$17 -> 0.028495174
B14: ='Data Sheet'!A23 -> Selling and admin | F14: ='Data Sheet'!B23/'Data Sheet'!B$17 -> 0.0058089346 | G14: ='Data Sheet'!C23/'Data Sheet'!C$17 -> 0.0038508056 | H14: ='Data Sheet'!D23/'Data Sheet'!D$17 -> 0.0071026582 | I14: ='Data Sheet'!E23/'Data Sheet'!E$17 -> 0.0061369773 | J14: ='Data Sheet'!F23/'Data Sheet'!F$17 -> 0.0050601836 | K14: ='Data Sheet'!G23/'Data Sheet'!G$17 -> 0.0038053986 | L14: ='Data Sheet'!H23/'Data Sheet'!H$17 -> 0.0061340082 | M14: ='Data Sheet'!I23/'Data Sheet'!I$17 -> 0.0051083963 | ... O14: ='Data Sheet'!K23/'Data Sheet'!K$17 -> 0
B15: ='Data Sheet'!A24 -> Other Expenses | F15: ='Data Sheet'!B24/'Data Sheet'!B$17 -> 0.022300554 | G15: ='Data Sheet'!C24/'Data Sheet'!C$17 -> 0.020324469 | H15: ='Data Sheet'!D24/'Data Sheet'!D$17 -> 0.027360572 | I15: ='Data Sheet'!E24/'Data Sheet'!E$17 -> 0.04062679 | J15: ='Data Sheet'!F24/'Data Sheet'!F$17 -> 0.025188191 | K15: ='Data Sheet'!G24/'Data Sheet'!G$17 -> 0.019962971 | L15: ='Data Sheet'!H24/'Data Sheet'!H$17 -> 0.033423717 | M15: ='Data Sheet'!I24/'Data Sheet'!I$17 -> 0.027736192 | ... O15: ='Data Sheet'!K24/'Data Sheet'!K$17 -> 0.20540249
B16: ='Data Sheet'!A25 -> Other Income | F16: ='Data Sheet'!B25/'Data Sheet'!B$17 -> 0.00032371772 | G16: ='Data Sheet'!C25/'Data Sheet'!C$17 -> -0.0024606231 | H16: ='Data Sheet'!D25/'Data Sheet'!D$17 -> 0.0023124934 | I16: ='Data Sheet'!E25/'Data Sheet'!E$17 -> -0.0039413032 | J16: ='Data Sheet'!F25/'Data Sheet'!F$17 -> 0.0059244229 | K16: ='Data Sheet'!G25/'Data Sheet'!G$17 -> 0.010931127 | L16: ='Data Sheet'!H25/'Data Sheet'!H$17 -> 0.0094058809 | M16: ='Data Sheet'!I25/'Data Sheet'!I$17 -> 0.0085711347 | ... O16: ='Data Sheet'!K25/'Data Sheet'!K$17 -> 0.1003235
B17: ='Data Sheet'!A26 -> Depreciation | F17: ='Data Sheet'!B26/'Data Sheet'!B$17 -> 0.06168621 | G17: ='Data Sheet'!C26/'Data Sheet'!C$17 -> 0.047085482 | H17: ='Data Sheet'!D26/'Data Sheet'!D$17 -> 0.047677478 | I17: ='Data Sheet'!E26/'Data Sheet'!E$17 -> 0.057905791 | J17: ='Data Sheet'!F26/'Data Sheet'!F$17 -> 0.058605443 | K17: ='Data Sheet'!G26/'Data Sheet'!G$17 -> 0.040998558 | L17: ='Data Sheet'!H26/'Data Sheet'!H$17 -> 0.045034948 | M17: ='Data Sheet'!I26/'Data Sheet'!I$17 -> 0.046695542 | ... O17: ='Data Sheet'!K26/'Data Sheet'!K$17 -> 0.051765784
B18: ='Data Sheet'!A27 -> Interest | F18: ='Data Sheet'!B27/'Data Sheet'!B$17 -> 0.067764909 | G18: ='Data Sheet'!C27/'Data Sheet'!C$17 -> 0.051450655 | H18: ='Data Sheet'!D27/'Data Sheet'!D$17 -> 0.046214472 | I18: ='Data Sheet'!E27/'Data Sheet'!E$17 -> 0.058164907 | J18: ='Data Sheet'!F27/'Data Sheet'!F$17 -> 0.049562244 | K18: ='Data Sheet'!G27/'Data Sheet'!G$17 -> 0.03394115 | L18: ='Data Sheet'!H27/'Data Sheet'!H$17 -> 0.041588335 | M18: ='Data Sheet'!I27/'Data Sheet'!I$17 -> 0.046312698 | ... O18: ='Data Sheet'!K27/'Data Sheet'!K$17 -> 0.049075322
B19: ='Data Sheet'!A28 -> Profit before tax | F19: ='Data Sheet'!B28/'Data Sheet'!B$17 -> 0.092223581 | G19: ='Data Sheet'!C28/'Data Sheet'!C$17 -> 0.10636287 | H19: ='Data Sheet'!D28/'Data Sheet'!D$17 -> 0.13176493 | I19: ='Data Sheet'!E28/'Data Sheet'!E$17 -> 0.041090473 | J19: ='Data Sheet'!F28/'Data Sheet'!F$17 -> 0.15049036 | K19: ='Data Sheet'!G28/'Data Sheet'!G$17 -> 0.20321648 | L19: ='Data Sheet'!H28/'Data Sheet'!H$17 -> 0.034074476 | M19: ='Data Sheet'!I28/'Data Sheet'!I$17 -> 0.076454522 | ... O19: ='Data Sheet'!K28/'Data Sheet'!K$17 -> 0.15770745
B20: ='Data Sheet'!A29 -> Tax | F20: ='Data Sheet'!B29/'Data Sheet'!B28 -> 0.32644306 | G20: ='Data Sheet'!C29/'Data Sheet'!C28 -> 0.20101947 | H20: ='Data Sheet'!D29/'Data Sheet'!D28 -> 0.3262894 | I20: ='Data Sheet'!E29/'Data Sheet'!E28 -> -0.30069698 | J20: ='Data Sheet'!F29/'Data Sheet'!F28 -> 0.34473575 | K20: ='Data Sheet'!G29/'Data Sheet'!G28 -> 0.29608338 | L20: ='Data Sheet'!H29/'Data Sheet'!H28 -> 0.26808134 | M20: ='Data Sheet'!I29/'Data Sheet'!I28 -> 0.3293722 | ... O20: ='Data Sheet'!K29/'Data Sheet'!K28 -> 0.12793162
B21: ='Data Sheet'!A30 -> Net profit | F21: ='Data Sheet'!B30/'Data Sheet'!B$17 -> 0.063358751 | G21: ='Data Sheet'!C30/'Data Sheet'!C$17 -> 0.086385942 | H21: ='Data Sheet'!D30/'Data Sheet'!D$17 -> 0.090128249 | I21: ='Data Sheet'!E30/'Data Sheet'!E$17 -> 0.054960041 | J21: ='Data Sheet'!F30/'Data Sheet'!F$17 -> 0.099086912 | K21: ='Data Sheet'!G30/'Data Sheet'!G$17 -> 0.14118234 | L21: ='Data Sheet'!H30/'Data Sheet'!H$17 -> 0.024969872 | M21: ='Data Sheet'!I30/'Data Sheet'!I$17 -> 0.050352559 | ... O21: ='Data Sheet'!K30/'Data Sheet'!K$17 -> 0.12032135
B23: ='Data Sheet'!A32 -> 0
A25: # | B25: Balance Sheet
B27: ='Data Sheet'!A57 -> Equity Share Capital | F27: ='Data Sheet'!B57/'Data Sheet'!B$66 -> 0.0034202602 | G27: ='Data Sheet'!C57/'Data Sheet'!C$66 -> 0.0032836795 | H27: ='Data Sheet'!D57/'Data Sheet'!D$66 -> 0.0026220197 | I27: ='Data Sheet'!E57/'Data Sheet'!E$66 -> 0.0022834168 | J27: ='Data Sheet'!F57/'Data Sheet'!F$66 -> 0.0020521463 | K27: ='Data Sheet'!G57/'Data Sheet'!G$66 -> 0.0015319236 | L27: ='Data Sheet'!H57/'Data Sheet'!H$66 -> 0.0014296639 | M27: ='Data Sheet'!I57/'Data Sheet'!I$66 -> 0.001338318 | ... O27: ='Data Sheet'!K57/'Data Sheet'!K$66 -> 0.0011309868
B28: ='Data Sheet'!A58 -> Reserves | F28: ='Data Sheet'!B58/'Data Sheet'!B$66 -> 0.25391739 | G28: ='Data Sheet'!C58/'Data Sheet'!C$66 -> 0.30114168 | H28: ='Data Sheet'!D58/'Data Sheet'!D$66 -> 0.30047824 | I28: ='Data Sheet'!E58/'Data Sheet'!E$66 -> 0.27536034 | J28: ='Data Sheet'!F58/'Data Sheet'!F$66 -> 0.3078763 | K28: ='Data Sheet'!G58/'Data Sheet'!G$66 -> 0.34097259 | L28: ='Data Sheet'!H58/'Data Sheet'!H$66 -> 0.31060279 | M28: ='Data Sheet'!I58/'Data Sheet'!I$66 -> 0.33946766 | ... O28: ='Data Sheet'!K58/'Data Sheet'!K$66 -> 0.36988089
B29: ='Data Sheet'!A59 -> Borrowings | F29: ='Data Sheet'!B59/'Data Sheet'!B$66 -> 0.49240384 | G29: ='Data Sheet'!C59/'Data Sheet'!C$66 -> 0.42832445 | H29: ='Data Sheet'!D59/'Data Sheet'!D$66 -> 0.41286793 | I29: ='Data Sheet'!E59/'Data Sheet'!E$66 -> 0.46596116 | J29: ='Data Sheet'!F59/'Data Sheet'!F$66 -> 0.4534224 | K29: ='Data Sheet'!G59/'Data Sheet'!G$66 -> 0.36764639 | L29: ='Data Sheet'!H59/'Data Sheet'!H$66 -> 0.38402861 | M29: ='Data Sheet'!I59/'Data Sheet'!I$66 -> 0.38606745 | ... O29: ='Data Sheet'!K59/'Data Sheet'!K$66 -> 0.36825672
B30: ='Data Sheet'!A60 -> Other Liabilities | F30: ='Data Sheet'!B60/'Data Sheet'!B$66 -> 0.25025851 | G30: ='Data Sheet'!C60/'Data Sheet'!C$66 -> 0.26725019 | H30: ='Data Sheet'!D60/'Data Sheet'!D$66 -> 0.28403181 | I30: ='Data Sheet'!E60/'Data Sheet'!E$66 -> 0.25639508 | J30: ='Data Sheet'!F60/'Data Sheet'!F$66 -> 0.23664916 | K30: ='Data Sheet'!G60/'Data Sheet'!G$66 -> 0.2898491 | L30: ='Data Sheet'!H60/'Data Sheet'!H$66 -> 0.30393894 | M30: ='Data Sheet'!I60/'Data Sheet'!I$66 -> 0.27312657 | ... O30: ='Data Sheet'!K60/'Data Sheet'!K$66 -> 0.2607314
B31: Total Liability | F31: ='Data Sheet'!B61/'Data Sheet'!B$66 -> 1 | G31: ='Data Sheet'!C61/'Data Sheet'!C$66 -> 1 | H31: ='Data Sheet'!D61/'Data Sheet'!D$66 -> 1 | I31: ='Data Sheet'!E61/'Data Sheet'!E$66 -> 1 | J31: ='Data Sheet'!F61/'Data Sheet'!F$66 -> 1 | K31: ='Data Sheet'!G61/'Data Sheet'!G$66 -> 1 | L31: ='Data Sheet'!H61/'Data Sheet'!H$66 -> 1 | M31: ='Data Sheet'!I61/'Data Sheet'!I$66 -> 1 | ... O31: ='Data Sheet'!K61/'Data Sheet'!K$66 -> 1
B32: ='Data Sheet'!A62 -> Net Block | F32: ='Data Sheet'!B62/'Data Sheet'!B$66 -> 0.66734845 | G32: ='Data Sheet'!C62/'Data Sheet'!C$66 -> 0.62898771 | H32: ='Data Sheet'!D62/'Data Sheet'!D$66 -> 0.5456937 | I32: ='Data Sheet'!E62/'Data Sheet'!E$66 -> 0.47098316 | J32: ='Data Sheet'!F62/'Data Sheet'!F$66 -> 0.44112311 | K32: ='Data Sheet'!G62/'Data Sheet'!G$66 -> 0.50833397 | L32: ='Data Sheet'!H62/'Data Sheet'!H$66 -> 0.49611711 | M32: ='Data Sheet'!I62/'Data Sheet'!I$66 -> 0.49347076 | ... O32: ='Data Sheet'!K62/'Data Sheet'!K$66 -> 0.43590086
B33: ='Data Sheet'!A63 -> Capital Work in Progress | F33: ='Data Sheet'!B63/'Data Sheet'!B$66 -> 0.049576729 | G33: ='Data Sheet'!C63/'Data Sheet'!C$66 -> 0.064695009 | H33: ='Data Sheet'!D63/'Data Sheet'!D$66 -> 0.10356542 | I33: ='Data Sheet'!E63/'Data Sheet'!E$66 -> 0.20627371 | J33: ='Data Sheet'!F63/'Data Sheet'!F$66 -> 0.22129204 | K33: ='Data Sheet'!G63/'Data Sheet'!G$66 -> 0.086037102 | L33: ='Data Sheet'!H63/'Data Sheet'!H$66 -> 0.10528216 | M33: ='Data Sheet'!I63/'Data Sheet'!I$66 -> 0.13021615 | ... O33: ='Data Sheet'!K63/'Data Sheet'!K$66 -> 0.081178896
B34: ='Data Sheet'!A64 -> Investments | F34: ='Data Sheet'!B64/'Data Sheet'!B$66 -> 0.015521845 | G34: ='Data Sheet'!C64/'Data Sheet'!C$66 -> 0.0159726 | H34: ='Data Sheet'!D64/'Data Sheet'!D$66 -> 0.016498689 | I34: ='Data Sheet'!E64/'Data Sheet'!E$66 -> 0.0095509027 | J34: ='Data Sheet'!F64/'Data Sheet'!F$66 -> 0.050467849 | K34: ='Data Sheet'!G64/'Data Sheet'!G$66 -> 0.025141868 | L34: ='Data Sheet'!H64/'Data Sheet'!H$66 -> 0.022827125 | M34: ='Data Sheet'!I64/'Data Sheet'!I$66 -> 0.031794926 | ... O34: ='Data Sheet'!K64/'Data Sheet'!K$66 -> 0.037889912
B35: ='Data Sheet'!A65 -> Other Assets | F35: ='Data Sheet'!B65/'Data Sheet'!B$66 -> 0.26755298 | G35: ='Data Sheet'!C65/'Data Sheet'!C$66 -> 0.29034468 | H35: ='Data Sheet'!D65/'Data Sheet'!D$66 -> 0.33424218 | I35: ='Data Sheet'!E65/'Data Sheet'!E$66 -> 0.31319223 | J35: ='Data Sheet'!F65/'Data Sheet'!F$66 -> 0.28711701 | K35: ='Data Sheet'!G65/'Data Sheet'!G$66 -> 0.38048706 | L35: ='Data Sheet'!H65/'Data Sheet'!H$66 -> 0.37577361 | M35: ='Data Sheet'!I65/'Data Sheet'!I$66 -> 0.34451816 | ... O35: ='Data Sheet'!K65/'Data Sheet'!K$66 -> 0.44503033
B36: Total Asset | F36: ='Data Sheet'!B66/'Data Sheet'!B$66 -> 1 | G36: ='Data Sheet'!C66/'Data Sheet'!C$66 -> 1 | H36: ='Data Sheet'!D66/'Data Sheet'!D$66 -> 1 | I36: ='Data Sheet'!E66/'Data Sheet'!E$66 -> 1 | J36: ='Data Sheet'!F66/'Data Sheet'!F$66 -> 1 | K36: ='Data Sheet'!G66/'Data Sheet'!G$66 -> 1 | L36: ='Data Sheet'!H66/'Data Sheet'!H$66 -> 1 | M36: ='Data Sheet'!I66/'Data Sheet'!I$66 -> 1 | ... O36: ='Data Sheet'!K66/'Data Sheet'!K$66 -> 1
B37: ='Data Sheet'!A67 -> Receivables | F37: ='Data Sheet'!B67/'Data Sheet'!B$66 -> 0.047145049 | G37: ='Data Sheet'!C67/'Data Sheet'!C$66 -> 0.051147113 | H37: ='Data Sheet'!D67/'Data Sheet'!D$66 -> 0.062370968 | I37: ='Data Sheet'!E67/'Data Sheet'!E$66 -> 0.034175391 | J37: ='Data Sheet'!F67/'Data Sheet'!F$66 -> 0.030483206 | K37: ='Data Sheet'!G67/'Data Sheet'!G$66 -> 0.037952007 | L37: ='Data Sheet'!H67/'Data Sheet'!H$66 -> 0.033884458 | M37: ='Data Sheet'!I67/'Data Sheet'!I$66 -> 0.03312008 | ... O37: ='Data Sheet'!K67/'Data Sheet'!K$66 -> 0.041753808
B38: ='Data Sheet'!A68 -> Inventory | F38: ='Data Sheet'!B68/'Data Sheet'!B$66 -> 0.12948128 | G38: ='Data Sheet'!C68/'Data Sheet'!C$66 -> 0.13693596 | H38: ='Data Sheet'!D68/'Data Sheet'!D$66 -> 0.12672805 | I38: ='Data Sheet'!E68/'Data Sheet'!E$66 -> 0.10448339 | J38: ='Data Sheet'!F68/'Data Sheet'!F$66 -> 0.096824609 | K38: ='Data Sheet'!G68/'Data Sheet'!G$66 -> 0.17195715 | L38: ='Data Sheet'!H68/'Data Sheet'!H$66 -> 0.15738177 | M38: ='Data Sheet'!I68/'Data Sheet'!I$66 -> 0.16592949 | ... O38: ='Data Sheet'!K68/'Data Sheet'!K$66 -> 0.12149765
B39: ='Data Sheet'!A69 -> Cash & Bank | F39: ='Data Sheet'!B69/'Data Sheet'!B$66 -> 0.016874041 | G39: ='Data Sheet'!C69/'Data Sheet'!C$66 -> 0.011558117 | H39: ='Data Sheet'!D69/'Data Sheet'!D$66 -> 0.053895137 | I39: ='Data Sheet'!E69/'Data Sheet'!E$66 -> 0.091055985 | J39: ='Data Sheet'!F69/'Data Sheet'!F$66 -> 0.087066722 | K39: ='Data Sheet'!G69/'Data Sheet'!G$66 -> 0.088469858 | L39: ='Data Sheet'!H69/'Data Sheet'!H$66 -> 0.098385572 | M39: ='Data Sheet'!I69/'Data Sheet'!I$66 -> 0.054182134 | ... O39: ='Data Sheet'!K69/'Data Sheet'!K$66 -> 0.1519935

Sheet Ratio Analysis
B2: Ratio Analysis
B5: Particulars | C5: ='Data Sheet'!B16 -> 42825 | D5: ='Data Sheet'!C16 -> 43190 | E5: ='Data Sheet'!D16 -> 43555 | F5: ='Data Sheet'!E16 -> 43921 | G5: ='Data Sheet'!F16 -> 44286 | H5: ='Data Sheet'!G16 -> 44651 | I5: ='Data Sheet'!H16 -> 45016 | J5: ='Data Sheet'!I16 -> 45382 | ... L5: ='Data Sheet'!K16 -> 46112 | M5: LTM | N5: line chart | O5: mean | P5: median
B7: SalesGrowth | D7: =IFERROR(Historical!D7/Historical!C7-1,0) -> 0.29366592 | E7: =IFERROR(Historical!E7/Historical!D7-1,0) -> 0.17827701 | F7: =IFERROR(Historical!F7/Historical!E7-1,0) -> -0.13486792 | G7: =IFERROR(Historical!G7/Historical!F7-1,0) -> 0.088822519 | H7: =IFERROR(Historical!H7/Historical!G7-1,0) -> 0.83332707 | I7: =IFERROR(Historical!I7/Historical!H7-1,0) -> 0.13383116 | J7: =IFERROR(Historical!J7/Historical!I7-1,0) -> 0.05450711 | K7: =IFERROR(Historical!K7/Historical!J7-1,0) -> -0.035324503 | L7: =IFERROR(Historical!L7/Historical!K7-1,0) -> 0.098599725 | O7: =AVERAGE(D7:L7) -> 0.1678709 | P7: =MEDIAN(C7:L7) -> 0.098599725
B8: EBITDA Growth | D8: =IFERROR(Historical!D19/Historical!C19-1,0) -> 0.2118947 | E8: =IFERROR(Historical!E19/Historical!D19-1,0) -> 0.269107 | F8: =IFERROR(Historical!F19/Historical!E19-1,0) -> -0.37596408 | G8: =IFERROR(Historical!G19/Historical!F19-1,0) -> 0.70811817 | H8: =IFERROR(Historical!H19/Historical!G19-1,0) -> 0.93844781 | I8: =IFERROR(Historical!I19/Historical!H19-1,0) -> -0.52779056 | J8: =IFERROR(Historical!J19/Historical!I19-1,0) -> 0.52447212 | K8: =IFERROR(Historical!K19/Historical!J19-1,0) -> -0.19291828 | L8: =IFERROR(Historical!L19/Historical!K19-1,0) -> 0.29135314 | O8: =AVERAGE(D8:L8) -> 0.20519111 | P8: =MEDIAN(C8:L8) -> 0.269107
B9: EBIT Growth | D9: =IFERROR((Historical!D19-Historical!D25)/(Historical!C19-Historical!C25),0) -> 1.2986033 | E9: =IFERROR((Historical!E19-Historical!E25)/(Historical!D19-Historical!D25),0) -> 1.291439 | F9: =IFERROR((Historical!F19-Historical!F25)/(Historical!E19-Historical!E25),0) -> 0.50822755 | G9: =IFERROR((Historical!G19-Historical!G25)/(Historical!F19-Historical!F25),0) -> 2.0482358 | H9: =IFERROR((Historical!H19-Historical!H25)/(Historical!G19-Historical!G25),0) -> 2.1364604 | I9: =IFERROR((Historical!I19-Historical!I25)/(Historical!H19-Historical!H25),0) -> 0.33207502 | J9: =IFERROR((Historical!J19-Historical!J25)/(Historical!I19-Historical!I25),0) -> 1.8174791 | K9: =IFERROR((Historical!K19-Historical!K25)/(Historical!J19-Historical!J25),0) -> 0.67130348 | L9: =IFERROR((Historical!L19-Historical!L25)/(Historical!K19-Historical!K25),0) -> 1.4717501 | O9: =AVERAGE(D9:L9) -> 1.2861749 | P9: =MEDIAN(C9:L9) -> 1.2986033
B10: Net Profit Growth | D10: =IFERROR(Historical!D34/Historical!C34-1,0) -> 0.830617 | E10: =IFERROR(Historical!E34/Historical!D34-1,0) -> 0.16502385 | F10: =IFERROR(Historical!F34/Historical!E34-1,0) -> -0.42576419 | G10: =IFERROR(Historical!G34/Historical!F34-1,0) -> 0.75855513 | H10: =IFERROR(Historical!H34/Historical!G34-1,0) -> 1.6132432 | I10: =IFERROR(Historical!I34/Historical!H34-1,0) -> -0.86668735 | J10: =IFERROR(Historical!J34/Historical!I34-1,0) -> 1.8987587 | K10: =IFERROR(Historical!K34/Historical!J34-1,0) -> -0.5426201 | L10: =IFERROR(Historical!L34/Historical!K34-1,0) -> 1.019017 | O10: =AVERAGE(D10:L10) -> 0.49446036 | P10: =MEDIAN(C10:L10) -> 0.75855513
B11: Dividend Growth | D11: =IFERROR(Historical!D22/Historical!C22-1,0) -> -0.017781316 | E11: =IFERROR(Historical!E22/Historical!D22-1,0) -> 0.058362605 | F11: =IFERROR(Historical!F22/Historical!E22-1,0) -> 0.088843503 | G11: =IFERROR(Historical!G22/Historical!F22-1,0) -> -0.072215709 | H11: =IFERROR(Historical!H22/Historical!G22-1,0) -> 0.25549659 | I11: =IFERROR(Historical!I22/Historical!H22-1,0) -> 0.38929147 | J11: =IFERROR(Historical!J22/Historical!I22-1,0) -> 0.17429731 | K11: =IFERROR(Historical!K22/Historical!J22-1,0) -> 0.037877853 | L11: =IFERROR(Historical!L22/Historical!K22-1,0) -> 0.082025678 | O11: =AVERAGE(D11:L11) -> 0.11068866 | P11: =MEDIAN(C11:L11) -> 0.082025678
B14: Gross Margin | C14: =IFERROR(Historical!C14,0) -> 0.24946047 | D14: =IFERROR(Historical!D14,0) -> 0.2315349 | E14: =IFERROR(Historical!E14,0) -> 0.25780761 | F14: =IFERROR(Historical!F14,0) -> 0.20786624 | G14: =IFERROR(Historical!G14,0) -> 0.282982 | H14: =IFERROR(Historical!H14,0) -> 0.29099343 | I14: =IFERROR(Historical!I14,0) -> 0.1508496 | J14: =IFERROR(Historical!J14,0) -> 0.19373621 | ... L14: =IFERROR(Historical!L14,0) -> 0.36362754 | O14: =AVERAGE(C14:L14) -> 0.24001429 | P14: =MEDIAN(C14:L14) -> 0.24049769
B15: Operating Margin | C15: =IFERROR((Historical!C19-Historical!C25)/Historical!C7,0) -> 0.15966477 | D15: =IFERROR((Historical!D19-Historical!D25)/Historical!D7,0) -> 0.16027414 | E15: =IFERROR((Historical!E19-Historical!E25)/Historical!E7,0) -> 0.17566691 | F15: =IFERROR((Historical!F19-Historical!F25)/Historical!F7,0) -> 0.10319668 | G15: =IFERROR((Historical!G19-Historical!G25)/Historical!G7,0) -> 0.19412818 | H15: =IFERROR((Historical!H19-Historical!H25)/Historical!H7,0) -> 0.22622651 | I15: =IFERROR((Historical!I19-Historical!I25)/Historical!I7,0) -> 0.066256929 | J15: =IFERROR((Historical!J19-Historical!J25)/Historical!J7,0) -> 0.11419608 | ... L15: =IFERROR((Historical!L19-Historical!L25)/Historical!L7,0) -> 0.10645927 | O15: =AVERAGE(C15:L15) -> 0.13855368 | P15: =MEDIAN(C15:L15) -> 0.13693043
B16: EBITDA Margin | C16: =IFERROR(Historical!C20,0) -> 0.22135098 | D16: =IFERROR(Historical!D20,0) -> 0.20735963 | E16: =IFERROR(Historical!E20,0) -> 0.22334438 | F16: =IFERROR(Historical!F20,0) -> 0.16110247 | G16: =IFERROR(Historical!G20,0) -> 0.25273363 | H16: =IFERROR(Historical!H20,0) -> 0.26722507 | I16: =IFERROR(Historical!I20,0) -> 0.11129188 | J16: =IFERROR(Historical!J20,0) -> 0.16089163 | ... L16: =IFERROR(Historical!L20,0) -> 0.15822505 | O16: =AVERAGE(C16:L16) -> 0.18981324 | P16: =MEDIAN(C16:L16) -> 0.18423105
